/home/ruppaal/696DS/allennlp/env/lib/python3.6/site-packages/h5py/__init__.py:36: FutureWarning: Conversion of the second argument of issubdtype from `float` to `np.floating` is deprecated. In future, it will be treated as `np.float64 == np.dtype(float).type`.
  from ._conv import register_converters as _register_converters
/home/ruppaal/696DS/allennlp/env/lib/python3.6/site-packages/psycopg2/__init__.py:144: UserWarning: The psycopg2 wheel package will be renamed from release 2.8; in order to keep installing from binary please use "pip install psycopg2-binary" instead. For details see: <http://initd.org/psycopg/docs/install.html#binary-install-from-pypi>.
  """)
2018-03-29 21:38:51,320 - INFO - allennlp.common.params - random_seed = 13370
2018-03-29 21:38:51,524 - INFO - allennlp.common.params - numpy_seed = 1337
2018-03-29 21:38:51,524 - INFO - allennlp.common.params - pytorch_seed = 133
2018-03-29 21:38:52,665 - INFO - allennlp.common.checks - Pytorch version: 0.3.1
2018-03-29 21:38:52,667 - INFO - allennlp.commands.train - Recovering from prior training at output/squad_copy.
2018-03-29 21:38:52,733 - ERROR - allennlp.commands.train - Value for 'train_data_path' in training configuration does not match that the value in the serialization directory we're recovering from: data/NewsQA/train_dump.json != data/squad/train-v1.1.json
2018-03-29 21:38:52,733 - ERROR - allennlp.commands.train - Value for 'validation_data_path' in training configuration does not match that the value in the serialization directory we're recovering from: data/NewsQA/dev_dump.json != data/squad/dev-v1.1.json
2018-03-29 21:38:52,733 - ERROR - allennlp.commands.train - Value for 'model.text_field_embedder.tokens.trainable' in training configuration does not match that the value in the serialization directory we're recovering from: True != False
Traceback (most recent call last):
  File "/cm/shared/apps/python/3.6.1/lib/python3.6/runpy.py", line 193, in _run_module_as_main
    "__main__", mod_spec)
  File "/cm/shared/apps/python/3.6.1/lib/python3.6/runpy.py", line 85, in _run_code
    exec(code, run_globals)
  File "/home/ruppaal/696DS/allennlp/allennlp/run.py", line 18, in <module>
    main(prog="python -m allennlp.run")
  File "/home/ruppaal/696DS/allennlp/allennlp/commands/__init__.py", line 63, in main
    args.func(args)
  File "/home/ruppaal/696DS/allennlp/allennlp/commands/train.py", line 99, in train_model_from_args
    args.recover)
  File "/home/ruppaal/696DS/allennlp/allennlp/commands/train.py", line 129, in train_model_from_file
    return train_model(params, serialization_dir, file_friendly_logging, recover)
  File "/home/ruppaal/696DS/allennlp/allennlp/commands/train.py", line 250, in train_model
    create_serialization_dir(params, serialization_dir, recover)
  File "/home/ruppaal/696DS/allennlp/allennlp/commands/train.py", line 217, in create_serialization_dir
    raise ConfigurationError("Training configuration does not match the configuration we're "
allennlp.common.checks.ConfigurationError: "Training configuration does not match the configuration we're recovering from."
