Traceback (most recent call last):
  File "process_logits.py", line 327, in <module>
    main()
  File "process_logits.py", line 289, in main
    print(top_ids[0])
  File "/home/iankit/anaconda3/lib/python3.6/site-packages/pandas/core/series.py", line 601, in __getitem__
    result = self.index.get_value(self, key)
  File "/home/iankit/anaconda3/lib/python3.6/site-packages/pandas/core/indexes/base.py", line 2477, in get_value
    tz=getattr(series.dtype, 'tz', None))
  File "pandas/_libs/index.pyx", line 98, in pandas._libs.index.IndexEngine.get_value
  File "pandas/_libs/index.pyx", line 106, in pandas._libs.index.IndexEngine.get_value
  File "pandas/_libs/index.pyx", line 154, in pandas._libs.index.IndexEngine.get_loc
  File "pandas/_libs/hashtable_class_helper.pxi", line 759, in pandas._libs.hashtable.Int64HashTable.get_item
  File "pandas/_libs/hashtable_class_helper.pxi", line 765, in pandas._libs.hashtable.Int64HashTable.get_item
KeyError: 0
